Traceback (most recent call last):
  File "/Users/schugani/opt/anaconda3/lib/python3.9/site-packages/jupyter_cache/executors/utils.py", line 51, in single_nb_execution
    executenb(
  File "/Users/schugani/opt/anaconda3/lib/python3.9/site-packages/nbclient/client.py", line 1204, in execute
    return NotebookClient(nb=nb, resources=resources, km=km, **kwargs).execute()
  File "/Users/schugani/opt/anaconda3/lib/python3.9/site-packages/nbclient/util.py", line 84, in wrapped
    return just_run(coro(*args, **kwargs))
  File "/Users/schugani/opt/anaconda3/lib/python3.9/site-packages/nbclient/util.py", line 62, in just_run
    return loop.run_until_complete(coro)
  File "/Users/schugani/opt/anaconda3/lib/python3.9/asyncio/base_events.py", line 647, in run_until_complete
    return future.result()
  File "/Users/schugani/opt/anaconda3/lib/python3.9/site-packages/nbclient/client.py", line 663, in async_execute
    await self.async_execute_cell(
  File "/Users/schugani/opt/anaconda3/lib/python3.9/site-packages/nbclient/client.py", line 965, in async_execute_cell
    await self._check_raise_for_error(cell, cell_index, exec_reply)
  File "/Users/schugani/opt/anaconda3/lib/python3.9/site-packages/nbclient/client.py", line 862, in _check_raise_for_error
    raise CellExecutionError.from_cell_and_msg(cell, exec_reply_content)
nbclient.exceptions.CellExecutionError: An error occurred while executing the following cell:
------------------
class Labradoodle(Dog):
    def __init__(self, name, age, fur, bark = "Woof"):
        super().__init__(name, age, bark)
        self.fur = fur
    def printFur(self):
        print(self.name + "'s fur is", self.fur)
------------------

[0;31m---------------------------------------------------------------------------[0m
[0;31mNameError[0m                                 Traceback (most recent call last)
Input [0;32mIn [1][0m, in [0;36m<cell line: 1>[0;34m()[0m
[0;32m----> 1[0m [38;5;28;01mclass[39;00m [38;5;21;01mLabradoodle[39;00m([43mDog[49m):
[1;32m      2[0m     [38;5;28;01mdef[39;00m [38;5;21m__init__[39m([38;5;28mself[39m, name, age, fur, bark [38;5;241m=[39m [38;5;124m"[39m[38;5;124mWoof[39m[38;5;124m"[39m):
[1;32m      3[0m         [38;5;28msuper[39m()[38;5;241m.[39m[38;5;21m__init__[39m(name, age, bark)

[0;31mNameError[0m: name 'Dog' is not defined
NameError: name 'Dog' is not defined

