Traceback (most recent call last):
  File "/Users/schugani/opt/anaconda3/lib/python3.9/site-packages/jupyter_cache/executors/utils.py", line 51, in single_nb_execution
    executenb(
  File "/Users/schugani/opt/anaconda3/lib/python3.9/site-packages/nbclient/client.py", line 1204, in execute
    return NotebookClient(nb=nb, resources=resources, km=km, **kwargs).execute()
  File "/Users/schugani/opt/anaconda3/lib/python3.9/site-packages/nbclient/util.py", line 84, in wrapped
    return just_run(coro(*args, **kwargs))
  File "/Users/schugani/opt/anaconda3/lib/python3.9/site-packages/nbclient/util.py", line 62, in just_run
    return loop.run_until_complete(coro)
  File "/Users/schugani/opt/anaconda3/lib/python3.9/asyncio/base_events.py", line 647, in run_until_complete
    return future.result()
  File "/Users/schugani/opt/anaconda3/lib/python3.9/site-packages/nbclient/client.py", line 663, in async_execute
    await self.async_execute_cell(
  File "/Users/schugani/opt/anaconda3/lib/python3.9/site-packages/nbclient/client.py", line 965, in async_execute_cell
    await self._check_raise_for_error(cell, cell_index, exec_reply)
  File "/Users/schugani/opt/anaconda3/lib/python3.9/site-packages/nbclient/client.py", line 862, in _check_raise_for_error
    raise CellExecutionError.from_cell_and_msg(cell, exec_reply_content)
nbclient.exceptions.CellExecutionError: An error occurred while executing the following cell:
------------------
old_path = os.path.join(cur_path, "data.csv")
new_path = os.path.join(new_dir, "data.csv")
os.rename(old_path, new_path)
------------------

[0;31m---------------------------------------------------------------------------[0m
[0;31mFileNotFoundError[0m                         Traceback (most recent call last)
Input [0;32mIn [9][0m, in [0;36m<cell line: 3>[0;34m()[0m
[1;32m      1[0m old_path [38;5;241m=[39m os[38;5;241m.[39mpath[38;5;241m.[39mjoin(cur_path, [38;5;124m"[39m[38;5;124mdata.csv[39m[38;5;124m"[39m)
[1;32m      2[0m new_path [38;5;241m=[39m os[38;5;241m.[39mpath[38;5;241m.[39mjoin(new_dir, [38;5;124m"[39m[38;5;124mdata.csv[39m[38;5;124m"[39m)
[0;32m----> 3[0m [43mos[49m[38;5;241;43m.[39;49m[43mrename[49m[43m([49m[43mold_path[49m[43m,[49m[43m [49m[43mnew_path[49m[43m)[49m

[0;31mFileNotFoundError[0m: [Errno 2] No such file or directory: '/Users/schugani/data.csv' -> '/Users/schugani/datasets/data.csv'
FileNotFoundError: [Errno 2] No such file or directory: '/Users/schugani/data.csv' -> '/Users/schugani/datasets/data.csv'

